============================= test session starts ==============================
platform linux -- Python 3.11.10, pytest-8.3.4, pluggy-1.5.0
rootdir: /home/runner/workspace
configfile: pyproject.toml
plugins: typeguard-4.4.1
collected 0 items / 3 errors                                       

============================== ERRORS ==============================
___________ ERROR collecting tests/test_power_manager.py ___________
tests/test_power_manager.py:2: in <module>
    from evennia.utils.test_resources import EvenniaTest
.pythonlibs/lib/python3.11/site-packages/evennia/utils/__init__.py:14: in <module>
    from .utils import *
.pythonlibs/lib/python3.11/site-packages/evennia/utils/utils.py:44: in <module>
    from evennia.utils import logger
.pythonlibs/lib/python3.11/site-packages/evennia/utils/logger.py:370: in <module>
    class EvenniaLogFile(logfile.LogFile):
.pythonlibs/lib/python3.11/site-packages/evennia/utils/logger.py:385: in EvenniaLogFile
    _CHANNEL_LOG_NUM_TAIL_LINES = settings.CHANNEL_LOG_NUM_TAIL_LINES
.pythonlibs/lib/python3.11/site-packages/django/conf/__init__.py:102: in __getattr__
    self._setup(name)
.pythonlibs/lib/python3.11/site-packages/django/conf/__init__.py:82: in _setup
    raise ImproperlyConfigured(
E   django.core.exceptions.ImproperlyConfigured: Requested setting CHANNEL_LOG_NUM_TAIL_LINES, but settings are not configured. You must either define the environment variable DJANGO_SETTINGS_MODULE or call settings.configure() before accessing settings.
_______________ ERROR collecting tests/test_ship.py ________________
tests/test_ship.py:2: in <module>
    from evennia.utils.test_resources import EvenniaTest
.pythonlibs/lib/python3.11/site-packages/evennia/utils/__init__.py:14: in <module>
    from .utils import *
.pythonlibs/lib/python3.11/site-packages/evennia/utils/utils.py:44: in <module>
    from evennia.utils import logger
.pythonlibs/lib/python3.11/site-packages/evennia/utils/logger.py:370: in <module>
    class EvenniaLogFile(logfile.LogFile):
.pythonlibs/lib/python3.11/site-packages/evennia/utils/logger.py:385: in EvenniaLogFile
    _CHANNEL_LOG_NUM_TAIL_LINES = settings.CHANNEL_LOG_NUM_TAIL_LINES
.pythonlibs/lib/python3.11/site-packages/django/conf/__init__.py:102: in __getattr__
    self._setup(name)
.pythonlibs/lib/python3.11/site-packages/django/conf/__init__.py:82: in _setup
    raise ImproperlyConfigured(
E   django.core.exceptions.ImproperlyConfigured: Requested setting CHANNEL_LOG_NUM_TAIL_LINES, but settings are not configured. You must either define the environment variable DJANGO_SETTINGS_MODULE or call settings.configure() before accessing settings.
____________ ERROR collecting tests/test_spaceobject.py ____________
tests/test_spaceobject.py:2: in <module>
    from evennia.utils.test_resources import EvenniaTest
.pythonlibs/lib/python3.11/site-packages/evennia/utils/__init__.py:14: in <module>
    from .utils import *
.pythonlibs/lib/python3.11/site-packages/evennia/utils/utils.py:44: in <module>
    from evennia.utils import logger
.pythonlibs/lib/python3.11/site-packages/evennia/utils/logger.py:370: in <module>
    class EvenniaLogFile(logfile.LogFile):
.pythonlibs/lib/python3.11/site-packages/evennia/utils/logger.py:385: in EvenniaLogFile
    _CHANNEL_LOG_NUM_TAIL_LINES = settings.CHANNEL_LOG_NUM_TAIL_LINES
.pythonlibs/lib/python3.11/site-packages/django/conf/__init__.py:102: in __getattr__
    self._setup(name)
.pythonlibs/lib/python3.11/site-packages/django/conf/__init__.py:82: in _setup
    raise ImproperlyConfigured(
E   django.core.exceptions.ImproperlyConfigured: Requested setting CHANNEL_LOG_NUM_TAIL_LINES, but settings are not configured. You must either define the environment variable DJANGO_SETTINGS_MODULE or call settings.configure() before accessing settings.
===================== short test summary info ======================
ERROR tests/test_power_manager.py - django.core.exceptions.ImproperlyConfigured: Requested setting ...
ERROR tests/test_ship.py - django.core.exceptions.ImproperlyConfigured: Requested setting ...
ERROR tests/test_spaceobject.py - django.core.exceptions.ImproperlyConfigured: Requested setting ...
!!!!!!!!!!!!! Interrupted: 3 errors during collection !!!!!!!!!!!!!!
======================== 3 errors in 0.61s =========================